<?xml version="1.0" encoding="utf-8"?>
<!-- This URDF was automatically created by SolidWorks to URDF Exporter! Originally created by Stephen Brawner (brawner@gmail.com) 
     Commit Version: 1.6.0-4-g7f85cfe  Build Version: 1.6.7995.38578
     For more information, please see http://wiki.ros.org/sw_urdf_exporter -->
<robot
  name="toycar">
  <link
    name="dummy_link">
  </link>
  
  <joint
    name="dummy_joint"
    type="fixed">
    <parent
      link="dummy_link" />
    <child
      link="base_link" />
    <origin
      xyz="0 0 0"
      rpy="0 0 0" />
  </joint>
  
  <link
    name="base_link">
    <inertial>
      <origin
        xyz="-0.042877 1.1748E-08 0.29275"
        rpy="0 0 0" />
      <mass
        value="52.191" />
      <inertia
        ixx="1.4547"
        ixy="-1.4758E-06"
        ixz="0.13713"
        iyy="3.9353"
        iyz="1.4578E-08"
        izz="4.9977" />
    </inertial>
    <visual>
      <origin
        xyz="0 0 0"
        rpy="0 0 0" />
      <geometry>
        <mesh
          filename="package://toycar/meshes/base_link.STL" />
      </geometry>
      <material
        name="">
        <color
          rgba="1 1 1 1" />
      </material>
    </visual>
    <collision>
      <origin
        xyz="0 0 0"
        rpy="0 0 0" />
      <geometry>
        <mesh
          filename="package://toycar/meshes/base_link.STL" />
      </geometry>
    </collision>
  </link>
  <link
    name="FL_axle">
    <inertial>
      <origin
        xyz="-2.1389E-07 -0.033228 -0.10824"
        rpy="0 0 0" />
      <mass
        value="0.061704" />
      <inertia
        ixx="0.00028284"
        ixy="-3.6306E-10"
        ixz="-1.1782E-10"
        iyy="0.0002242"
        iyz="-4.3637E-06"
        izz="6.0365E-05" />
    </inertial>
    <visual>
      <origin
        xyz="0 0 0"
        rpy="0 0 0" />
      <geometry>
        <mesh
          filename="package://toycar/meshes/FL_axle.STL" />
      </geometry>
      <material
        name="">
        <color
          rgba="1 1 1 1" />
      </material>
    </visual>
    <collision>
      <origin
        xyz="0 0 0"
        rpy="0 0 0" />
      <geometry>
        <mesh
          filename="package://toycar/meshes/FL_axle.STL" />
      </geometry>
    </collision>
  </link>
  <joint
    name="FL_axle_chassis"
    type="revolute">
    <origin
      xyz="0.254 0.2159 0.2794"
      rpy="0 0 0" />
    <parent
      link="base_link" />
    <child
      link="FL_axle" />
    <axis
      xyz="0 0 1" />
    <limit
      lower="-0.698"
      upper="0.698"
      effort="30"
      velocity="100" />
  </joint>
  <transmission name="FL_axle_chassis_trans">
    <type>transmission_interface/SimpleTransmission</type>
    <joint name="FL_axle_chassis">
      <hardwareInterface>hardware_interface/EffortJointInterface</hardwareInterface>
    </joint>
    <actuator name="FL_axle_chassis_motor">
      <mechanicalReduction>1</mechanicalReduction>
      <hardwareInterface>hardware_interface/EffortJointInterface</hardwareInterface>
    </actuator>
  </transmission>
  <link
    name="FL_wheel">
    <inertial>
      <origin
        xyz="0 0 -0.0381"
        rpy="0 0 0" />
      <mass
        value="19.669" />
      <inertia
        ixx="0.0066187"
        ixy="-2.2273E-18"
        ixz="-7.5842E-19"
        iyy="0.0066187"
        iyz="-4.0053E-19"
        izz="0.011667" />
    </inertial>
    <visual>
      <origin
        xyz="0 0 0"
        rpy="0 0 0" />
      <geometry>
        <mesh
          filename="package://toycar/meshes/FL_wheel.STL" />
      </geometry>
      <material
        name="">
        <color
          rgba="0.29804 0.29804 0.29804 1" />
      </material>
    </visual>
    <collision>
      <origin
        xyz="0 0 0"
        rpy="0 0 0" />
      <geometry>
        <mesh
          filename="package://toycar/meshes/FL_wheel.STL" />
      </geometry>
    </collision>
  </link>
  <joint
    name="FL_wheel_axle"
    type="continuous">
    <origin
      xyz="0 0.0381 -0.1778"
      rpy="-1.5708 0 0" />
    <parent
      link="FL_axle" />
    <child
      link="FL_wheel" />
    <axis
      xyz="0 0 1" />
  </joint>
  <link
    name="FR_axle">
    <inertial>
      <origin
        xyz="2.1389E-07 0.033228 -0.10824"
        rpy="0 0 0" />
      <mass
        value="0.061704" />
      <inertia
        ixx="0.00028284"
        ixy="-3.6306E-10"
        ixz="1.1782E-10"
        iyy="0.0002242"
        iyz="4.3637E-06"
        izz="6.0365E-05" />
    </inertial>
    <visual>
      <origin
        xyz="0 0 0"
        rpy="0 0 0" />
      <geometry>
        <mesh
          filename="package://toycar/meshes/FR_axle.STL" />
      </geometry>
      <material
        name="">
        <color
          rgba="1 1 1 1" />
      </material>
    </visual>
    <collision>
      <origin
        xyz="0 0 0"
        rpy="0 0 0" />
      <geometry>
        <mesh
          filename="package://toycar/meshes/FR_axle.STL" />
      </geometry>
    </collision>
  </link>
  <joint
    name="FR_axle_chassis"
    type="revolute">
    <origin
      xyz="0.254 -0.2159 0.2794"
      rpy="0 0 0" />
    <parent
      link="base_link" />
    <child
      link="FR_axle" />
    <axis
      xyz="0 0 1" />
    <limit
      lower="-0.698"
      upper="0.698"
      effort="30"
      velocity="100" />
  </joint>
  <transmission name="FR_axle_chassis_trans">
    <type>transmission_interface/SimpleTransmission</type>
    <joint name="FR_axle_chassis">
      <hardwareInterface>hardware_interface/EffortJointInterface</hardwareInterface>
    </joint>
    <actuator name="FR_axle_chassis_motor">
      <mechanicalReduction>1</mechanicalReduction>
      <hardwareInterface>hardware_interface/EffortJointInterface</hardwareInterface>
    </actuator>
  </transmission>
  <link
    name="FR_wheel">
    <inertial>
      <origin
        xyz="0 -1.3878E-17 0.0381"
        rpy="0 0 0" />
      <mass
        value="19.669" />
      <inertia
        ixx="0.0066187"
        ixy="1.0816E-18"
        ixz="-4.9837E-19"
        iyy="0.0066187"
        iyz="-4.0009E-19"
        izz="0.011667" />
    </inertial>
    <visual>
      <origin
        xyz="0 0 0"
        rpy="0 0 0" />
      <geometry>
        <mesh
          filename="package://toycar/meshes/FR_wheel.STL" />
      </geometry>
      <material
        name="">
        <color
          rgba="0.29804 0.29804 0.29804 1" />
      </material>
    </visual>
    <collision>
      <origin
        xyz="0 0 0"
        rpy="0 0 0" />
      <geometry>
        <mesh
          filename="package://toycar/meshes/FR_wheel.STL" />
      </geometry>
    </collision>
  </link>
  <joint
    name="FR_wheel_axle"
    type="continuous">
    <origin
      xyz="0 -0.0381 -0.1778"
      rpy="-1.5708 0 0" />
    <parent
      link="FR_axle" />
    <child
      link="FR_wheel" />
    <axis
      xyz="0 0 1" />
  </joint>
  <link
    name="BR_axle">
    <inertial>
      <origin
        xyz="2.1389E-07 0.033228 -0.10824"
        rpy="0 0 0" />
      <mass
        value="0.061704" />
      <inertia
        ixx="0.00028284"
        ixy="-3.6306E-10"
        ixz="1.1782E-10"
        iyy="0.0002242"
        iyz="4.3637E-06"
        izz="6.0365E-05" />
    </inertial>
    <visual>
      <origin
        xyz="0 0 0"
        rpy="0 0 0" />
      <geometry>
        <mesh
          filename="package://toycar/meshes/BR_axle.STL" />
      </geometry>
      <material
        name="">
        <color
          rgba="1 1 1 1" />
      </material>
    </visual>
    <collision>
      <origin
        xyz="0 0 0"
        rpy="0 0 0" />
      <geometry>
        <mesh
          filename="package://toycar/meshes/BR_axle.STL" />
      </geometry>
    </collision>
  </link>
  <joint
    name="BR_axle_chassis"
    type="fixed">
    <origin
      xyz="-0.254 -0.2159 0.2794"
      rpy="0 0 0" />
    <parent
      link="base_link" />
    <child
      link="BR_axle" />
    <axis
      xyz="0 0 0" />
  </joint>
  <link
    name="BR_wheel">
    <inertial>
      <origin
        xyz="0 -1.3878E-17 0.0381"
        rpy="0 0 0" />
      <mass
        value="19.669" />
      <inertia
        ixx="0.0066187"
        ixy="-4.6602E-19"
        ixz="-3.6188E-20"
        iyy="0.0066187"
        iyz="-2.4546E-20"
        izz="0.011667" />
    </inertial>
    <visual>
      <origin
        xyz="0 0 0"
        rpy="0 0 0" />
      <geometry>
        <mesh
          filename="package://toycar/meshes/BR_wheel.STL" />
      </geometry>
      <material
        name="">
        <color
          rgba="0.29804 0.29804 0.29804 1" />
      </material>
    </visual>
    <collision>
      <origin
        xyz="0 0 0"
        rpy="0 0 0" />
      <geometry>
        <mesh
          filename="package://toycar/meshes/BR_wheel.STL" />
      </geometry>
    </collision>
  </link>
  <joint
    name="BR_wheel_axle"
    type="continuous">
    <origin
      xyz="0 -0.0381 -0.1778"
      rpy="-1.5708 0 0" />
    <parent
      link="BR_axle" />
    <child
      link="BR_wheel" />
    <axis
      xyz="0 0 1" />
  </joint>
  <transmission name="BR_wheel_axle_trans">
    <type>transmission_interface/SimpleTransmission</type>
    <joint name="BR_wheel_axle">
      <hardwareInterface>hardware_interface/VelocityJointInterface</hardwareInterface>
    </joint>
    <actuator name="BR_wheel_axle_motor">
      <mechanicalReduction>1</mechanicalReduction>
    </actuator>
  </transmission>
  <link
    name="BL_axle">
    <inertial>
      <origin
        xyz="-2.1389E-07 -0.033228 -0.10824"
        rpy="0 0 0" />
      <mass
        value="0.061704" />
      <inertia
        ixx="0.00028284"
        ixy="-3.6306E-10"
        ixz="-1.1782E-10"
        iyy="0.0002242"
        iyz="-4.3637E-06"
        izz="6.0365E-05" />
    </inertial>
    <visual>
      <origin
        xyz="0 0 0"
        rpy="0 0 0" />
      <geometry>
        <mesh
          filename="package://toycar/meshes/BL_axle.STL" />
      </geometry>
      <material
        name="">
        <color
          rgba="1 1 1 1" />
      </material>
    </visual>
    <collision>
      <origin
        xyz="0 0 0"
        rpy="0 0 0" />
      <geometry>
        <mesh
          filename="package://toycar/meshes/BL_axle.STL" />
      </geometry>
    </collision>
  </link>
  <joint
    name="BL_axle_chassis"
    type="fixed">
    <origin
      xyz="-0.254 0.2159 0.2794"
      rpy="0 0 0" />
    <parent
      link="base_link" />
    <child
      link="BL_axle" />
    <axis
      xyz="0 0 0" />
  </joint>
  <link
    name="BL_wheel">
    <inertial>
      <origin
        xyz="5.5511E-17 1.3878E-17 -0.0381"
        rpy="0 0 0" />
      <mass
        value="19.669" />
      <inertia
        ixx="0.0066187"
        ixy="4.4054E-19"
        ixz="-1.3271E-18"
        iyy="0.0066187"
        iyz="-6.6236E-19"
        izz="0.011667" />
    </inertial>
    <visual>
      <origin
        xyz="0 0 0"
        rpy="0 0 0" />
      <geometry>
        <mesh
          filename="package://toycar/meshes/BL_wheel.STL" />
      </geometry>
      <material
        name="">
        <color
          rgba="0.29804 0.29804 0.29804 1" />
      </material>
    </visual>
    <collision>
      <origin
        xyz="0 0 0"
        rpy="0 0 0" />
      <geometry>
        <mesh
          filename="package://toycar/meshes/BL_wheel.STL" />
      </geometry>
    </collision>
  </link>
  <joint
    name="BL_wheel_axle"
    type="continuous">
    <origin
      xyz="0 0.0381 -0.1778"
      rpy="-1.5708 0 0" />
    <parent
      link="BL_axle" />
    <child
      link="BL_wheel" />
    <axis
      xyz="0 0 1" />
  </joint>
  <transmission name="BL_wheel_axle_trans">
    <type>transmission_interface/SimpleTransmission</type>
    <joint name="BL_wheel_axle">
      <hardwareInterface>hardware_interface/VelocityJointInterface</hardwareInterface>
    </joint>
    <actuator name="BL_wheel_axle_motor">
      <mechanicalReduction>1</mechanicalReduction>
    </actuator>
  </transmission>
  <link
    name="mlr_link1">
    <inertial>
      <origin
        xyz="-3.4833E-15 -5.1625E-15 0.066013"
        rpy="0 0 0" />
      <mass
        value="0.021881" />
      <inertia
        ixx="0.011816"
        ixy="-1.1858E-20"
        ixz="-2.873E-19"
        iyy="0.011591"
        iyz="-2.3152E-19"
        izz="0.021954" />
    </inertial>
    <visual>
      <origin
        xyz="0 0 0"
        rpy="0 0 0" />
      <geometry>
        <mesh
          filename="package://transformer/meshes/mlr_link1.STL" />
      </geometry>
      <material
        name="">
        <color
          rgba="0.79216 0.81961 0.93333 1" />
      </material>
    </visual>
    <collision>
      <origin
        xyz="0 0 0"
        rpy="0 0 0" />
      <geometry>
        <mesh
          filename="package://transformer/meshes/mlr_link1.STL" />
      </geometry>
    </collision>
  </link>
  <joint
    name="link1_chassis"
    type="revolute">
    <origin
      xyz="0 0 0.24252"
      rpy="0 0 0.0025505" />
    <parent
      link="base_link" />
    <child
      link="mlr_link1" />
    <axis
      xyz="0 0 -1" />
    <limit
      lower="0"
      upper="6.283"
      effort="30"
      velocity="100" />
  </joint>
  <transmission name="link1_chassis_trans">
    <type>transmission_interface/SimpleTransmission</type>
    <joint name="link1_chassis">
      <hardwareInterface>hardware_interface/EffortJointInterface</hardwareInterface>
    </joint>
    <actuator name="link1_chassis_motor">
      <mechanicalReduction>1</mechanicalReduction>
      <hardwareInterface>hardware_interface/EffortJointInterface</hardwareInterface>
    </actuator>
  </transmission>
  <link
    name="mlr_link2">
    <inertial>
      <origin
        xyz="0.24339 -9.8435E-08 2.7091E-06"
        rpy="0 0 0" />
      <mass
        value="0.226679" />
      <inertia
        ixx="0.022841"
        ixy="8.6807E-08"
        ixz="1.271E-06"
        iyy="0.080308"
        iyz="2.3327E-08"
        izz="0.058468" />
    </inertial>
    <visual>
      <origin
        xyz="0 0 0"
        rpy="0 0 0" />
      <geometry>
        <mesh
          filename="package://transformer/meshes/mlr_link2.STL" />
      </geometry>
      <material
        name="">
        <color
          rgba="0.79216 0.81961 0.93333 1" />
      </material>
    </visual>
    <collision>
      <origin
        xyz="0 0 0"
        rpy="0 0 0" />
      <geometry>
        <mesh
          filename="package://transformer/meshes/mlr_link2.STL" />
      </geometry>
    </collision>
  </link>
  <joint
    name="link2_link1"
    type="revolute">
    <origin
      xyz="0 0 0.10414"
      rpy="1.5708 0 3.1416" />
    <parent
      link="mlr_link1" />
    <child
      link="mlr_link2" />
    <axis
      xyz="0 0 1" />
    <limit
      lower="0"
      upper="3.14"
      effort="300"
      velocity="100" />
  </joint>
  <transmission name="link2_link1_trans">
    <type>transmission_interface/SimpleTransmission</type>
    <joint name="link2_link1">
      <hardwareInterface>hardware_interface/EffortJointInterface</hardwareInterface>
    </joint>
    <actuator name="link2_link1_motor">
      <mechanicalReduction>1</mechanicalReduction>
      <hardwareInterface>hardware_interface/EffortJointInterface</hardwareInterface>
    </actuator>
  </transmission>
  <link
    name="mlr_link3">
    <inertial>
      <origin
        xyz="0.50997 0.0031101 -7.5244E-06"
        rpy="0 0 0" />
      <mass
        value="0.03717" />
      <inertia
        ixx="0.076483"
        ixy="8.4905E-08"
        ixz="9.2587E-06"
        iyy="0.35221"
        iyz="8.051E-09"
        izz="0.27699" />
    </inertial>
    <visual>
      <origin
        xyz="0 0 0"
        rpy="0 0 0" />
      <geometry>
        <mesh
          filename="package://transformer/meshes/mlr_link3.STL" />
      </geometry>
      <material
        name="">
        <color
          rgba="0.79216 0.81961 0.93333 1" />
      </material>
    </visual>
    <collision>
      <origin
        xyz="0 0 0"
        rpy="0 0 0" />
      <geometry>
        <mesh
          filename="package://transformer/meshes/mlr_link3.STL" />
      </geometry>
    </collision>
  </link>
  <joint
    name="link3_link2"
    type="revolute">
    <origin
      xyz="0.45688 -0.0031098 0"
      rpy="-3.1416 0 3.1416" />
    <parent
      link="mlr_link2" />
    <child
      link="mlr_link3" />
    <axis
      xyz="0 0 1" />
    <limit
      lower="0"
      upper="6.283"
      effort="300"
      velocity="100" />
  </joint>
  <transmission name="link3_link2_trans">
    <type>transmission_interface/SimpleTransmission</type>
    <joint name="link3_link2">
      <hardwareInterface>hardware_interface/EffortJointInterface</hardwareInterface>
    </joint>
    <actuator name="link3_link2_motor">
      <mechanicalReduction>1</mechanicalReduction>
      <hardwareInterface>hardware_interface/EffortJointInterface</hardwareInterface>
    </actuator>
  </transmission>
  <link
    name="mlr_link4">
    <inertial>
      <origin
        xyz="0.016727 6.741E-08 1.784E-08"
        rpy="0 0 0" />
      <mass
        value="0.037398" />
      <inertia
        ixx="0.0014131"
        ixy="-5.5962E-10"
        ixz="1.0584E-10"
        iyy="0.0017439"
        iyz="1.0599E-09"
        izz="0.00051617" />
    </inertial>
    <visual>
      <origin
        xyz="0 0 0"
        rpy="0 0 0" />
      <geometry>
        <mesh
          filename="package://transformer/meshes/mlr_link4.STL" />
      </geometry>
      <material
        name="">
        <color
          rgba="0.79216 0.81961 0.93333 1" />
      </material>
    </visual>
    <collision>
      <origin
        xyz="0 0 0"
        rpy="0 0 0" />
      <geometry>
        <mesh
          filename="package://transformer/meshes/mlr_link4.STL" />
      </geometry>
    </collision>
  </link>
  <joint
    name="link4_link3"
    type="revolute">
    <origin
      xyz="0.93948 0.0031098 0"
      rpy="-3.1416 0 3.1416" />
    <parent
      link="mlr_link3" />
    <child
      link="mlr_link4" />
    <axis
      xyz="0 0 1" />
    <limit
      lower="0"
      upper="6.283"
      effort="100"
      velocity="100" />
  </joint>
  <transmission name="link4_link3_trans">
    <type>transmission_interface/SimpleTransmission</type>
    <joint name="link4_link3">
      <hardwareInterface>hardware_interface/EffortJointInterface</hardwareInterface>
    </joint>
    <actuator name="link4_link3_motor">
      <mechanicalReduction>1</mechanicalReduction>
      <hardwareInterface>hardware_interface/EffortJointInterface</hardwareInterface>
    </actuator>
  </transmission>
  <link
    name="mlr_link5">
    <inertial>
      <origin
        xyz="-1.0445E-05 -0.00012914 0.2039"
        rpy="0 0 0" />
      <mass
        value="0.036459" />
      <inertia
        ixx="0.0030391"
        ixy="-2.7105E-20"
        ixz="-2.5269E-19"
        iyy="0.0030391"
        iyz="3.7635E-19"
        izz="0.00021501" />
    </inertial>
    <visual>
      <origin
        xyz="0 0 0"
        rpy="0 0 0" />
      <geometry>
        <mesh
          filename="package://transformer/meshes/mlr_link5.STL" />
      </geometry>
      <material
        name="">
        <color
          rgba="0.79216 0.81961 0.93333 1" />
      </material>
    </visual>
    <collision>
      <origin
        xyz="0 0 0"
        rpy="0 0 0" />
      <geometry>
        <mesh
          filename="package://transformer/meshes/mlr_link5.STL" />
      </geometry>
    </collision>
  </link>
  <joint
    name="link5_link4"
    type="revolute">
    <origin
      xyz="0 0 0.00012957"
      rpy="1.5708 -0.080704 1.5708" />
    <parent
      link="mlr_link4" />
    <child
      link="mlr_link5" />
    <axis
      xyz="0 0 1" />
    <limit
      lower="0"
      upper="6.283"
      effort="30"
      velocity="100" />
  </joint>
  <transmission name="link5_link4_trans">
    <type>transmission_interface/SimpleTransmission</type>
    <joint name="link5_link4">
      <hardwareInterface>hardware_interface/EffortJointInterface</hardwareInterface>
    </joint>
    <actuator name="link5_link4_motor">
      <mechanicalReduction>1</mechanicalReduction>
      <hardwareInterface>hardware_interface/EffortJointInterface</hardwareInterface>
    </actuator>
  </transmission>
  <link
    name="mlr_link6">
    <inertial>
      <origin
        xyz="2.2204E-16 2.9143E-16 0.15461"
        rpy="0 0 0" />
      <mass
        value="0.038855" />
      <inertia
        ixx="0.002921"
        ixy="1.2038E-08"
        ixz="6.3631E-19"
        iyy="0.0029208"
        iyz="-3.5832E-19"
        izz="8.329E-05" />
    </inertial>
    <visual>
      <origin
        xyz="0 0 0"
        rpy="0 0 0" />
      <geometry>
        <mesh
          filename="package://transformer/meshes/mlr_link6.STL" />
      </geometry>
      <material
        name="">
        <color
          rgba="0.79216 0.81961 0.93333 1" />
      </material>
    </visual>
    <collision>
      <origin
        xyz="0 0 0"
        rpy="0 0 0" />
      <geometry>
        <mesh
          filename="package://transformer/meshes/mlr_link6.STL" />
      </geometry>
    </collision>
  </link>
  <joint
    name="link6_link5"
    type="prismatic">
    <origin
      xyz="-1.0445E-05 -0.00012914 0.1016"
      rpy="0 0 3.0214" />
    <parent
      link="mlr_link5" />
    <child
      link="mlr_link6" />
    <axis
      xyz="0 0 1" />
    <limit
      lower="0"
      upper="0.254"
      effort="30"
      velocity="100" />
  </joint>
  <transmission name="link6_link5_trans">
    <type>transmission_interface/SimpleTransmission</type>
    <joint name="link6_link5">
      <hardwareInterface>hardware_interface/EffortJointInterface</hardwareInterface>
    </joint>
    <actuator name="link6_link5_motor">
      <mechanicalReduction>1</mechanicalReduction>
      <hardwareInterface>hardware_interface/EffortJointInterface</hardwareInterface>
    </actuator>
  </transmission>
  <link
    name="finger1">
    <inertial>
      <origin
        xyz="0.0032305 -0.019321 0.0002415"
        rpy="0 0 0" />
      <mass
        value="0.0012184" />
      <inertia
        ixx="2.1571E-07"
        ixy="5.6309E-08"
        ixz="-1.6294E-09"
        iyy="4.6481E-08"
        iyz="2.0983E-09"
        izz="2.5937E-07" />
    </inertial>
    <visual>
      <origin
        xyz="0 0 0"
        rpy="0 0 0" />
      <geometry>
        <mesh
          filename="package://transformer/meshes/finger1.STL" />
      </geometry>
      <material
        name="">
        <color
          rgba="0.79216 0.81961 0.93333 1" />
      </material>
    </visual>
    <collision>
      <origin
        xyz="0 0 0"
        rpy="0 0 0" />
      <geometry>
        <mesh
          filename="package://transformer/meshes/finger1.STL" />
      </geometry>
    </collision>
  </link>
  <joint
    name="finger1_link6"
    type="revolute">
    <origin
      xyz="-0.0016676 0.020119 0.30352"
      rpy="-1.5708 0 -1.5313" />
    <parent
      link="mlr_link6" />
    <child
      link="finger1" />
    <axis
      xyz="0 0 -1" />
    <limit
      lower="0"
      upper="1.57"
      effort="30"
      velocity="100" />
  </joint>
  <transmission name="finger1_link6_trans">
    <type>transmission_interface/SimpleTransmission</type>
    <joint name="finger1_link6">
      <hardwareInterface>hardware_interface/EffortJointInterface</hardwareInterface>
    </joint>
    <actuator name="finger1_link6_motor">
      <mechanicalReduction>1</mechanicalReduction>
      <hardwareInterface>hardware_interface/EffortJointInterface</hardwareInterface>
    </actuator>
  </transmission>
  <link
    name="finger2">
    <inertial>
      <origin
        xyz="0.003506 -0.019305 0.00011543"
        rpy="0 0 0" />
      <mass
        value="0.0012184" />
      <inertia
        ixx="2.1565E-07"
        ixy="5.6348E-08"
        ixz="1.4889E-23"
        iyy="4.6481E-08"
        iyz="-5.8525E-23"
        izz="2.5943E-07" />
    </inertial>
    <visual>
      <origin
        xyz="0 0 0"
        rpy="0 0 0" />
      <geometry>
        <mesh
          filename="package://transformer/meshes/finger2.STL" />
      </geometry>
      <material
        name="">
        <color
          rgba="0.79216 0.81961 0.93333 1" />
      </material>
    </visual>
    <collision>
      <origin
        xyz="0 0 0"
        rpy="0 0 0" />
      <geometry>
        <mesh
          filename="package://transformer/meshes/finger2.STL" />
      </geometry>
    </collision>
  </link>
  <joint
    name="finger2_link6"
    type="revolute">
    <origin
      xyz="0.0016826 -0.020388 0.30354"
      rpy="-1.5708 0 1.6475" />
    <parent
      link="mlr_link6" />
    <child
      link="finger2" />
    <axis
      xyz="0 0 -1" />
    <limit
      lower="0"
      upper="1.57"
      effort="30"
      velocity="100" />
  </joint>
  <transmission name="finger2_link6_trans">
    <type>transmission_interface/SimpleTransmission</type>
    <joint name="finger2_link6">
      <hardwareInterface>hardware_interface/EffortJointInterface</hardwareInterface>
    </joint>
    <actuator name="finger2_link6_motor">
      <mechanicalReduction>1</mechanicalReduction>
      <hardwareInterface>hardware_interface/EffortJointInterface</hardwareInterface>
    </actuator>
  </transmission>
</robot>
